<?xml version="1.0" encoding="utf-8"?>
<!-- This URDF was automatically created by SolidWorks to URDF Exporter! Originally created by Stephen Brawner (brawner@gmail.com) 
     Commit Version: 1.6.0-4-g7f85cfe  Build Version: 1.6.7995.38578
     For more information, please see http://wiki.ros.org/sw_urdf_exporter -->
<robot
  name="Chulubot_v3">

  <link
    name="base_link">
    <inertial>
      <origin
        xyz="-0.00106753594179072 2.16230235951052E-05 0.0430350704818082"
        rpy="0 0 0" />
      <mass
        value="0.449921989924034" />
      <inertia
        ixx="0.000882697284967844"
        ixy="-1.55905123751096E-05"
        ixz="2.49050193542988E-06"
        iyy="0.00101275036596537"
        iyz="-2.45140663479319E-10"
        izz="0.00187226553928426" />
    </inertial>
    <visual>
      <origin
        xyz="0 0 0"
        rpy="0 0 0" />
      <geometry>
        <mesh
          filename="package://chulubot_description/meshes/base_link.STL" />
      </geometry>
      <material
        name="">
        <color
          rgba="0.792156862745098 0.819607843137255 0.933333333333333 1" />
      </material>
    </visual>
    <collision>
      <origin
        xyz="0 0 0"
        rpy="0 0 0" />
      <geometry>
        <mesh
          filename="package://chulubot_description/meshes/base_link.STL" />
      </geometry>
    </collision>
  </link>
  <link
    name="RW_Link">
    <inertial>
      <origin
        xyz="-1.27500309431551E-06 -0.00151905091921613 5.70926108823394E-07"
        rpy="0 0 0" />
      <mass
        value="0.0309248678399296" />
      <inertia
        ixx="1.14652931244595E-05"
        ixy="2.44341763535491E-09"
        ixz="-4.7560893507066E-09"
        iyy="2.13403627399623E-05"
        iyz="4.65097170421401E-09"
        izz="1.145776443775E-05" />
    </inertial>
    <visual>
      <origin
        xyz="0 0 0"
        rpy="0 0 0" />
      <geometry>
        <mesh
          filename="package://chulubot_description/meshes/RW_Link.STL" />
      </geometry>
      <material
        name="">
        <color
          rgba="0.603921568627451 0.647058823529412 0.686274509803922 1" />
      </material>
    </visual>
    <collision>
      <origin
        xyz="0 0 0"
        rpy="0 0 0" />
      <geometry>
        <mesh
          filename="package://chulubot_description/meshes/RW_Link.STL" />
      </geometry>
    </collision>
  </link>
  <joint
    name="RW_joint"
    type="continuous">
    <origin
      xyz="0.0002 0.0963 0.01725"
      rpy="0 0 0" />
    <parent
      link="base_link" />
    <child
      link="RW_Link" />
    <axis
      xyz="0 -1 0" />
    <limit
      effort="1.4"
      velocity="5.96" />
    <dynamics
      friction="0.1" />
  </joint>
  <link
    name="LW_Link">
    <inertial>
      <origin
        xyz="1.27500309431589E-06 0.0015190509192161 5.70926108868497E-07"
        rpy="0 0 0" />
      <mass
        value="0.0309248678399297" />
      <inertia
        ixx="1.14652931244595E-05"
        ixy="2.44341763535846E-09"
        ixz="4.75608935070421E-09"
        iyy="2.13403627399623E-05"
        iyz="-4.65097170421015E-09"
        izz="1.145776443775E-05" />
    </inertial>
    <visual>
      <origin
        xyz="0 0 0"
        rpy="0 0 0" />
      <geometry>
        <mesh
          filename="package://chulubot_description/meshes/LW_Link.STL" />
      </geometry>
      <material
        name="">
        <color
          rgba="0.603921568627451 0.647058823529412 0.686274509803922 1" />
      </material>
    </visual>
    <collision>
      <origin
        xyz="0 0 0"
        rpy="0 0 0" />
      <geometry>
        <mesh
          filename="package://chulubot_description/meshes/LW_Link.STL" />
      </geometry>
    </collision>
  </link>
  <joint
    name="LW_joint"
    type="continuous">
    <origin
      xyz="0.0002 -0.0963 0.01725"
      rpy="0 0 0" />
    <parent
      link="base_link" />
    <child
      link="LW_Link" />
    <axis
      xyz="0 1 0" />
    <limit
      effort="1.4"
      velocity="5.96" />
    <dynamics
      friction="0.1" />
  </joint>
  <link
    name="OAK-D_Link">
    <inertial>
      <origin
        xyz="0.00594449114290635 -0.000106083630455743 -0.00489429412500983"
        rpy="0 0 0" />
      <mass
        value="0.0212385024641858" />
      <inertia
        ixx="1.53825541195807E-05"
        ixy="2.5203334543623E-09"
        ixz="5.24230913003515E-09"
        iyy="1.54494848665998E-06"
        iyz="-2.38780789421046E-08"
        izz="1.41520715979904E-05" />
    </inertial>
    <visual>
      <origin
        xyz="0 0 0"
        rpy="0 0 3.1415" />
      <geometry>
        <mesh
          filename="package://chulubot_description/meshes/OAK-D_Link.STL" />
      </geometry>
      <material
        name="">
        <color
          rgba="0.792156862745098 0.819607843137255 0.933333333333333 1" />
      </material>
    </visual>
    <collision>
      <origin
        xyz="0 0 0"
        rpy="0 0 0" />
      <geometry>
        <mesh
          filename="package://chulubot_description/meshes/OAK-D_Link.STL" />
      </geometry>
    </collision>
  </link>
  <joint
    name="OAK-D_joint"
    type="fixed">
    <origin
      xyz="-0.084041 0.0004995 0.15854"
      rpy="0 0 3.1415" />
    <parent
      link="base_link" />
    <child
      link="OAK-D_Link" />
    <axis
      xyz="0 0 0" />
  </joint>
  <link
    name="Laser_scan_link">
    <inertial>
      <origin
        xyz="-0.0116619135783735 0.000421721352483171 -0.0237705092730101"
        rpy="0 0 0" />
      <mass
        value="0.0735134320395797" />
      <inertia
        ixx="1.81430727341253E-05"
        ixy="-3.1352737051652E-07"
        ixz="3.25184699103723E-07"
        iyy="2.39640853936973E-05"
        iyz="1.07177138939515E-08"
        izz="3.9441060130773E-05" />
    </inertial>
    <visual>
      <origin
        xyz="0 0 0"
        rpy="0 0 0" />
      <geometry>
        <mesh
          filename="package://chulubot_description/meshes/Laser_scan_link.STL" />
      </geometry>
      <material
        name="">
        <color
          rgba="0.792156862745098 0.819607843137255 0.933333333333333 1" />
      </material>
    </visual>
    <collision>
      <origin
        xyz="0 0 0"
        rpy="0 0 0" />
      <geometry>
        <mesh
          filename="package://chulubot_description/meshes/Laser_scan_link.STL" />
      </geometry>
    </collision>
  </link>
  <joint
    name="Laser_scan_joint"
    type="fixed">
    <origin
      xyz="0.016742 0.0019953 0.2"
      rpy="0 0 0" />
    <parent
      link="base_link" />
    <child
      link="Laser_scan_link" />
    <axis
      xyz="0 0 0" />
  </joint>

<transmission name="right_wheel_joint_trans">
    <type>transmission_interface/SimpleTransmission</type>
    <joint name="RW_joint"/>
    <actuator name="front_right_wheel_joint_motor">
      <hardwareInterface>EffortJointInterface</hardwareInterface>
      <mechanicalReduction>1</mechanicalReduction>
    </actuator>
  </transmission>

<transmission name="left_wheel_joint_trans">
    <type>transmission_interface/SimpleTransmission</type>
    <joint name="LW_joint"/>
    <actuator name="front_left_wheel_joint_motor">
      <hardwareInterface>EffortJointInterface</hardwareInterface>
      <mechanicalReduction>1</mechanicalReduction>
    </actuator>
  </transmission>

<include filename="$(find chulubot_description)/urdf/controllers.gazebo" />


</robot>